<?xml version='1.0' encoding='utf-8'?>
<mujocoinclude>
  <body name="bittle" pos="0 0 0.5">
    <freejoint />
    <geom type="mesh" rgba="0.7 0.7 0.7 1" mesh="base_link" />
    <geom type="mesh" rgba="0.7 0.7 0.7 1" mesh="front__1" />
    <geom type="mesh" rgba="0.7 0.7 0.7 1" mesh="rear__1" />
    <geom type="mesh" rgba="0.7 0.7 0.7 1" mesh="servo_rfs_1" />
    <geom type="mesh" rgba="0.7 0.7 0.7 1" mesh="screw_16_1" />
    <geom type="mesh" rgba="0.7 0.7 0.7 1" mesh="screw_7_1" />
    <geom type="mesh" rgba="0.7 0.7 0.7 1" mesh="servo_rrs__1" />
    <geom type="mesh" rgba="0.7 0.7 0.7 1" mesh="screw_1_1" />
    <geom type="mesh" rgba="0.7 0.7 0.7 1" mesh="screw_15_1" />
    <geom type="mesh" rgba="0.7 0.7 0.7 1" mesh="c_neck__1" />
    <geom type="mesh" rgba="0.7 0.7 0.7 1" mesh="screw_17_1" />
    <geom type="mesh" rgba="0.7 0.7 0.7 1" mesh="screw_21_1" />
    <geom type="mesh" rgba="0.7 0.7 0.7 1" mesh="screw_6_1" />
    <geom type="mesh" rgba="0.7 0.7 0.7 1" mesh="servo_lfs_1" />
    <geom type="mesh" rgba="0.7 0.7 0.7 1" mesh="screw_5_1" />
    <geom type="mesh" rgba="0.7 0.7 0.7 1" mesh="screw_10_1" />
    <geom type="mesh" rgba="0.7 0.7 0.7 1" mesh="servo_lrs__1" />
    <geom type="mesh" rgba="0.7 0.7 0.7 1" mesh="screw_13_1" />
    <geom type="mesh" rgba="0.7 0.7 0.7 1" mesh="screw_14_1" />
    <geom type="mesh" rgba="0.7 0.7 0.7 1" mesh="a_1" />
    <geom type="mesh" rgba="0.7 0.7 0.7 1" mesh="b__1" />
    <geom type="mesh" rgba="0.7 0.7 0.7 1" mesh="c_1" />
    <geom type="mesh" rgba="0.7 0.7 0.7 1" mesh="d_1" />
    <geom type="mesh" rgba="0.7 0.7 0.7 1" mesh="e_1" />
    <geom type="mesh" rgba="0.7 0.7 0.7 1" mesh="f_1" />
    <geom type="mesh" rgba="0.7 0.7 0.7 1" mesh="g_1" />
    <geom type="mesh" rgba="0.7 0.7 0.7 1" mesh="h__1" />
    <geom type="mesh" rgba="0.7 0.7 0.7 1" mesh="i_1" />
    <geom type="mesh" rgba="0.7 0.7 0.7 1" mesh="j__1" />
    <geom type="mesh" rgba="0.7 0.7 0.7 1" mesh="k_1" />
    <geom type="mesh" rgba="0.7 0.7 0.7 1" mesh="l_1" />
    <geom type="mesh" rgba="0.7 0.7 0.7 1" mesh="cover_1" />
    <geom type="mesh" rgba="0.7 0.7 0.7 1" mesh="logo_5_1" />
    <geom type="mesh" rgba="0.7 0.7 0.7 1" mesh="logo_1_1" />
    <geom type="mesh" rgba="0.7 0.7 0.7 1" mesh="logo_2_1" />
    <geom type="mesh" rgba="0.7 0.7 0.7 1" mesh="logo_3_1" />
    <geom type="mesh" rgba="0.7 0.7 0.7 1" mesh="logo_4_1" />
    <geom type="mesh" rgba="0.7 0.7 0.7 1" mesh="battery_1" />
    <body name="c_thrf__1" pos="0.0525 -0.0485 0.022">
      <joint name="shrfs_joint" pos="0 0 0" axis="0 1 0" />
      <geom pos="-0.0525 0.0485 -0.022" quat="1 0 0 0" type="mesh" rgba="0.7 0.7 0.7 1" mesh="c_thrf__1" />
      <geom pos="-0.0525 0.0485 -0.022" quat="1 0 0 0" type="mesh" rgba="0.7 0.7 0.7 1" mesh="th_rf_1" />
      <geom pos="-0.0525 0.0485 -0.022" quat="1 0 0 0" type="mesh" rgba="0.7 0.7 0.7 1" mesh="tho_rf__1" />
      <geom pos="-0.0525 0.0485 -0.022" quat="1 0 0 0" type="mesh" rgba="0.7 0.7 0.7 1" mesh="c_thorf_1" />
      <geom pos="-0.0525 0.0485 -0.022" type="mesh" rgba="0.7 0.7 0.7 1" mesh="screwm_3_1" />
      <geom pos="-0.0525 0.0485 -0.022" quat="1 0 0 0" type="mesh" rgba="0.7 0.7 0.7 1" mesh="tube__1" />
      <geom pos="-0.0525 0.0485 -0.022" type="mesh" rgba="0.7 0.7 0.7 1" mesh="screwm_4_1" />
      <body name="servos_rf_1" pos="-0.044433 0.00142 -0.011906">
        <joint name="shrft_joint" pos="0 0 0" axis="0 1 0" />
        <geom pos="-0.008067 0.04708 -0.010094" quat="1 0 0 0" type="mesh" rgba="0.7 0.7 0.7 1" mesh="servos_rf_1" />
        <geom pos="-0.008067 0.04708 -0.010094" quat="1 0 0 0" type="mesh" rgba="0.7 0.7 0.7 1" mesh="shank_rf_1" />
        <geom pos="-0.008067 0.04708 -0.010094" type="mesh" rgba="0.7 0.7 0.7 1" mesh="screw_9_1" />
        <geom pos="-0.008067 0.04708 -0.010094" type="mesh" rgba="0.7 0.7 0.7 1" mesh="screw_8_1" />
      </body>
    </body>
    <body name="c_thrr_1" pos="-0.0525 -0.0485 0.022">
      <joint name="shrrs_joint" pos="0 0 0" axis="0 -1 0" />
      <geom pos="0.0525 0.0485 -0.022" quat="1 0 0 0" type="mesh" rgba="0.7 0.7 0.7 1" mesh="c_thrr_1" />
      <geom pos="0.0525 0.0485 -0.022" quat="1 0 0 0" type="mesh" rgba="0.7 0.7 0.7 1" mesh="th_rr_1" />
      <geom pos="0.0525 0.0485 -0.022" quat="1 0 0 0" type="mesh" rgba="0.7 0.7 0.7 1" mesh="tho_rr_1" />
      <geom pos="0.0525 0.0485 -0.022" quat="1 0 0 0" type="mesh" rgba="0.7 0.7 0.7 1" mesh="c_thorr_1" />
      <geom pos="0.0525 0.0485 -0.022" type="mesh" rgba="0.7 0.7 0.7 1" mesh="screwm_1_1" />
      <geom pos="0.0525 0.0485 -0.022" quat="1 0 0 0" type="mesh" rgba="0.7 0.7 0.7 1" mesh="tube_rr_1" />
      <geom pos="0.0525 0.0485 -0.022" type="mesh" rgba="0.7 0.7 0.7 1" mesh="screwm_2_1" />
      <body name="servos_rr_1" pos="-0.044433 0.00142 -0.011906">
        <joint name="shrrt_joint" pos="0 0 0" axis="0 1 0" />
        <geom pos="0.096933 0.04708 -0.010094" quat="1 0 0 0" type="mesh" rgba="0.7 0.7 0.7 1" mesh="servos_rr_1" />
        <geom pos="0.096933 0.04708 -0.010094" quat="1 0 0 0" type="mesh" rgba="0.7 0.7 0.7 1" mesh="shank_rr_1" />
        <geom pos="0.096933 0.04708 -0.010094" type="mesh" rgba="0.7 0.7 0.7 1" mesh="screw_19_1" />
        <geom pos="0.096933 0.04708 -0.010094" type="mesh" rgba="0.7 0.7 0.7 1" mesh="screw_11_1" />
      </body>
    </body>
    <body name="servo_neck__1" pos="0.047554 0 0.035941">
      <joint name="neck_joint" pos="0 0 0" axis="-0.5 0 -0.866025" />
      <geom pos="-0.047554 0 -0.035941" quat="1 0 0 0" type="mesh" rgba="0.7 0.7 0.7 1" mesh="servo_neck__1" />
      <geom pos="-0.047554 0 -0.035941" quat="1 0 0 0" type="mesh" rgba="0.7 0.7 0.7 1" mesh="jaw_1" />
      <geom pos="-0.047554 0 -0.035941" quat="1 0 0 0" type="mesh" rgba="0.7 0.7 0.7 1" mesh="head__1" />
      <geom pos="-0.047554 0 -0.035941" type="mesh" rgba="0.7 0.7 0.7 1" mesh="screw_18_1" />
      <geom pos="-0.047554 0 -0.035941" type="mesh" rgba="0.7 0.7 0.7 1" mesh="screw_4_1" />
    </body>
    <body name="c_thlf_1" pos="0.0525 0.0485 0.022">
      <joint name="shlfs_joint" pos="0 0 0" axis="0 1 0" />
      <geom pos="-0.0525 -0.0485 -0.022" quat="1 0 0 0" type="mesh" rgba="0.7 0.7 0.7 1" mesh="c_thlf_1" />
      <geom pos="-0.0525 -0.0485 -0.022" quat="1 0 0 0" type="mesh" rgba="0.7 0.7 0.7 1" mesh="th_lf_1" />
      <geom pos="-0.0525 -0.0485 -0.022" quat="1 0 0 0" type="mesh" rgba="0.7 0.7 0.7 1" mesh="tho_lf_1" />
      <geom pos="-0.0525 -0.0485 -0.022" quat="1 0 0 0" type="mesh" rgba="0.7 0.7 0.7 1" mesh="c_tholf_1" />
      <geom pos="-0.0525 -0.0485 -0.022" type="mesh" rgba="0.7 0.7 0.7 1" mesh="screwm_6_1" />
      <geom pos="-0.0525 -0.0485 -0.022" quat="1 0 0 0" type="mesh" rgba="0.7 0.7 0.7 1" mesh="tube_lf_1" />
      <geom pos="-0.0525 -0.0485 -0.022" type="mesh" rgba="0.7 0.7 0.7 1" mesh="screwm_5_1" />
      <body name="servos_lf_1" pos="-0.044433 -0.00142 -0.011906">
        <joint name="shlft_joint" pos="0 0 0" axis="0 1 0" />
        <geom pos="-0.008067 -0.04708 -0.010094" quat="1 0 0 0" type="mesh" rgba="0.7 0.7 0.7 1" mesh="servos_lf_1" />
        <geom pos="-0.008067 -0.04708 -0.010094" quat="1 0 0 0" type="mesh" rgba="0.7 0.7 0.7 1" mesh="shank_lf_1" />
        <geom pos="-0.008067 -0.04708 -0.010094" type="mesh" rgba="0.7 0.7 0.7 1" mesh="screw_2_1" />
        <geom pos="-0.008067 -0.04708 -0.010094" type="mesh" rgba="0.7 0.7 0.7 1" mesh="screw_20_1" />
      </body>
    </body>
    <body name="c_thlr_1" pos="-0.0525 0.0485 0.022">
      <joint name="shlrs_joint" pos="0 0 0" axis="0 -1 0" />
      <geom pos="0.0525 -0.0485 -0.022" quat="1 0 0 0" type="mesh" rgba="0.7 0.7 0.7 1" mesh="c_thlr_1" />
      <geom pos="0.0525 -0.0485 -0.022" quat="1 0 0 0" type="mesh" rgba="0.7 0.7 0.7 1" mesh="th_lr__1" />
      <geom pos="0.0525 -0.0485 -0.022" quat="1 0 0 0" type="mesh" rgba="0.7 0.7 0.7 1" mesh="tho_lr_1" />
      <geom pos="0.0525 -0.0485 -0.022" quat="1 0 0 0" type="mesh" rgba="0.7 0.7 0.7 1" mesh="c_tholr__1" />
      <geom pos="0.0525 -0.0485 -0.022" type="mesh" rgba="0.7 0.7 0.7 1" mesh="screwm_8_1" />
      <geom pos="0.0525 -0.0485 -0.022" quat="1 0 0 0" type="mesh" rgba="0.7 0.7 0.7 1" mesh="tube_lr_1" />
      <geom pos="0.0525 -0.0485 -0.022" type="mesh" rgba="0.7 0.7 0.7 1" mesh="screwm_7_1" />
      <body name="servos_lr_1" pos="-0.044433 -0.001418 -0.011906">
        <joint name="shlrt_joint" pos="0 0 0" axis="0 1 0" />
        <geom pos="0.096933 -0.047082 -0.010094" quat="1 0 0 0" type="mesh" rgba="0.7 0.7 0.7 1" mesh="servos_lr_1" />
        <geom pos="0.096933 -0.047082 -0.010094" quat="1 0 0 0" type="mesh" rgba="0.7 0.7 0.7 1" mesh="shank_lr_1" />
        <geom pos="0.096933 -0.047082 -0.010094" type="mesh" rgba="0.7 0.7 0.7 1" mesh="screw_3_1" />
        <geom pos="0.096933 -0.047082 -0.010094" type="mesh" rgba="0.7 0.7 0.7 1" mesh="screw_12_1" />
      </body>
    </body>
  </body>
</mujocoinclude>